name: Workflow con fallback

on:
  workflow_dispatch:

jobs:
  primer-job:
    runs-on: ubuntu-latest
    timeout-minutes: 1 
    continue-on-error: true  
    outputs:
      resultado: ${{ steps.set-output.outputs.status }}
    steps:
      - name: Ejecutar algo que falla o no
        id: test
        run: |
          echo "Fallo intencional..."
          #exit 1  # cámbialo a 0 si quieres probar caso exitoso
        continue-on-error: true

      - name: Establecer resultado y anotar
        id: set-output
        run: |
          if [[ "${{ steps.test.outcome }}" == "failure" ]]; then
            echo "::error title=Fallo detectado::El paso 'test' falló intencionalmente"
            echo "status=FAIL" >> $GITHUB_OUTPUT
          else
            echo "::notice title=Éxito detectado::El paso 'test' se ejecutó correctamente"
            echo "status=OK" >> $GITHUB_OUTPUT
          fi

  segundo-job:
    runs-on: ubuntu-latest
    needs: primer-job
    if: needs.primer-job.outputs.resultado == 'FAIL'
    steps:
      - name: Mostrar mensaje de uso
        run: |
          echo "Se usó el segundo"
          echo "::notice title=Segundo job activado::El segundo job fue ejecutado porque el primero falló"
